Workbook

Sheet Dashboard
A1: 🏛 PhilGEPS Procurement Monitoring Dashboard | S1: 🏛 PhilGEPS Procurement Monitoring Dashboard
A2: Philippine Government Electronic Procurement System | Real-Time Bid Monitoring | S2: Philippine Government Electronic Procurement System | Real-Time Bid Monitoring
A3: =TODAY() -> 46193
A5: 📋 | D5: 📅 | G5: 📆 | J5: 💰 | M5: 🟢 | P5: ⚠️ | S5: 📤
A6: Total Bids Today | D6: Total Bids This Week | G6: Total Bids This Month | J6: Total ABC Value (₱) | M6: Active Bids | P6: Closing in 7 Days | S6: Pending
A7: =COUNTIFS('Bid Monitoring'!A:A,TODAY()) -> 2 | D7: =COUNTIFS('Bid Monitoring'!A:A,">="&TODAY()-WEEKDAY(TODAY(),2)+1,'Bid Monitoring'!A:A,"<="&TODAY()-WEEKDAY(TODAY(),2)+7) -> 6 | G7: =COUNTIFS('Bid Monitoring'!A:A,">="&DATE(YEAR(TODAY()),MONTH(TODAY()),1),'Bid Monitoring'!A:A,"<="&EOMONTH(TODAY(),0)) -> 32 | J7: =IFERROR(SUMIF('Bid Monitoring'!N:N,"<>Cancelled",'Bid Monitoring'!H:H),0) -> 35076413 | M7: =COUNTIF('Bid Monitoring'!N:N,"Pending")+COUNTIF('Bid Monitoring'!N:N,"Interested")+COUNTIF('Bid Monitoring'!N:N,"For Review")+COUNTIF('Bid Monitoring'!N:N,"For Canvas")+COUNTIF('Bid Monitoring'!N:N,"Under Evaluation")+COUNTIF('Bid Monitoring'!N:N,"Preparing Documents")+COUNTIF('Bid Monitoring'!N:N,"New")+COUNTIF('Bid Monitoring'!N:N,"Submitting") -> 18 | P7: =COUNTIFS('Bid Monitoring'!I:I,">="&TODAY(),'Bid Monitoring'!I:I,"<="&TODAY()+7) -> 8 | S7: =COUNTIF('Bid Monitoring'!N:N,"Pending") -> 2
A9: 📤 | D9: 🔍 | G9: 🏆 | J9: ❌ | M9: 🚫 | P9: 📊
A10: Submitted | D10: Under Evaluation | G10: Awarded / Won | J10: Lost | M10: Cancelled | P10: Success Rate
A11: =COUNTIF('Bid Monitoring'!N:N,"Submitted") -> 4 | D11: =COUNTIF('Bid Monitoring'!N:N,"Under Evaluation") -> 2 | G11: =COUNTIF('Bid Monitoring'!N:N,"Awarded") -> 0 | J11: =COUNTIF('Bid Monitoring'!N:N,"Lost") -> 0 | M11: =COUNTIF('Bid Monitoring'!N:N,"Cancelled") -> 8 | P11: =IFERROR(COUNTIF('Bid Monitoring'!N:N,"Awarded")/COUNTIF('Bid Monitoring'!N:N,"Submitted"),0) -> 0
A14: 🚨 HIGH PRIORITY FLAGS — ABC > ₱5,000,000 & Closing > 10 Days
A15: # | B15: Reference Number | C15: Project Title | D15: Procuring Entity | E15: Region | F15: ABC (₱) | G15: Closing Date | H15: Days Left | I15: Category | J15: Status
A16: 1 | B16: ⬅ Add data in "Bid Monitoring" sheet — High-priority bids (ABC > ₱5M, Closing > 10 days) will appear here automatically
A17: 2
A18: 3
A19: 4
A20: 5
A21: 6
A22: 7
A23: 8
A24: 9
A25: 10
A27: 📊 Analytics & Reporting Charts
A28: 📈 Opportunities by Region [Charts will render after adding data to Bid Monitoring sheet] | J28: 📈 Opportunities by Category [Charts will render after adding data to Bid Monitoring sheet]
A45: 📈 Monthly Opportunity Trend [Charts will render after adding data to Bid Monitoring sheet] | J45: 📈 ABC Value by Region (₱) [Charts will render after adding data to Bid Monitoring sheet]
A62: 📈 Active vs Closed Opportunities [Charts will render after adding data to Bid Monitoring sheet] | J62: 📈 Bid Status Distribution [Charts will render after adding data to Bid Monitoring sheet]

Sheet Bid Monitoring
A1: 📋 BID MONITORING MASTERLIST — PhilGEPS Procurement Opportunities
A2: Date Monitored | B2: Reference Number | C2: Procuring Entity | D2: Project Title | E2: Category | F2: Region | G2: Province | H2: ABC (₱) | I2: Closing Date | J2: Closing Time | K2: Days Remaining | L2: Priority Level | M2: Assigned To | N2: Status | O2: Remarks | P2: Date Submitted | Q2: Bid Amount | R2: Result | S2: Opportunity Score | T2: ABC Flag >5M+10days | U2: Recommendation | V2: RFQ FILE
A3: 46180 | B3: 13023463 | C3: CARAGA REGIONAL HOSPITAL | D3: SUPPLY AND DELIVERY OF VARIOUS INKS AND CONSUMABLES UNDER SINGLE YEAR FRAMEWORK AGREEMENT | E3: Office Supplies | F3: CARAGA | G3: SURIGAO DEL NORTE | H3: 4091665 | I3: 46196 | J3: 0.41666667 | K3: =IF(I3="","",I3-TODAY()) -> 3 | L3: =IF(I3="","",IF(I3-TODAY()<=3,"High",IF(I3-TODAY()<=7,"Medium","Low"))) -> High | N3: Pending | O3: FOR REVIEW | R3: Pending | S3: =IF(H3="","",IFERROR(IF(H3>5000000,30,IF(H3>=1000000,20,10))+IF(I3-TODAY()>14,30,IF(I3-TODAY()>=7,20,10))+IF(R3="Won",40,IF(R3="Lost",10,20)),"")) -> 50 | T3: =IF(OR(H3="",I3=""),"",IF(AND(H3>5000000,I3-TODAY()>10),"🚨 FLAG","—")) -> — | U3: =IF(S3="","",IF(S3>=70,"✅ Highly Recommended",IF(S3>=50,"🔶 Consider","❌ Low Priority"))) -> 🔶 Consider | V3: E:\za\Agencies\May 30, 2026\CRH\A. TECHNICAL SPECS.pdf
A4: 46180 | B4: 13037704 | C4: CABADBARAN SOUTH CENTRAL ELEMENTARY SCHOOL - CABADBARAN CITY | D4: PR No.: 2026-06-001 sbfp Q-2026-05-001 SBFP Rice for SBFP 2026 | E4: Food Stuff | F4: CARAGA | G4: AGUSAN DEL NORTE | H4: 371200 | I4: 46183 | J4: 0.33333333 | K4: =IF(I10="","",I10-TODAY()) -> -12 | L4: Low | N4: Cancelled | O4: Cancelled by sir omar | R4: Cancelled | S4: =IF(H10="","",IFERROR(IF(H10>5000000,30,IF(H10>=1000000,20,10))+IF(I10-TODAY()>14,30,IF(I10-TODAY()>=7,20,10))+IF(R10="Won",40,IF(R10="Lost",10,20)),"")) -> 40 | T4: =IF(OR(H10="",I10=""),"",IF(AND(H10>5000000,I10-TODAY()>10),"🚨 FLAG","—")) -> — | U4: =IF(S10="","",IF(S10>=70,"✅ Highly Recommended",IF(S10>=50,"🔶 Consider","❌ Low Priority"))) -> ❌ Low Priority
A5: 46180 | B5: 13037984 | C5: CABADBARAN SOUTH CENTRAL ELEMENTARY SCHOOL - CABADBARAN CITY | D5: PR No.: 2026-06-001 sbfp Q-2026-05-003 SBFP VEGETABLES for SBFP | E5: Food Stuff | F5: CARAGA | G5: AGUSAN DEL NORTE | H5: 349756 | I5: 46181 | J5: 0.33333333 | K5: =IF(I11="","",I11-TODAY()) -> -11 | L5: Low | N5: Cancelled | O5: Cancelled by sir omar | R5: Cancelled | S5: =IF(H11="","",IFERROR(IF(H11>5000000,30,IF(H11>=1000000,20,10))+IF(I11-TODAY()>14,30,IF(I11-TODAY()>=7,20,10))+IF(R11="Won",40,IF(R11="Lost",10,20)),"")) -> 40 | T5: =IF(OR(H11="",I11=""),"",IF(AND(H11>5000000,I11-TODAY()>10),"🚨 FLAG","—")) -> — | U5: =IF(S11="","",IF(S11>=70,"✅ Highly Recommended",IF(S11>=50,"🔶 Consider","❌ Low Priority"))) -> ❌ Low Priority
A6: 46180 | B6: 13037836 | C6: CABADBARAN SOUTH CENTRAL ELEMENTARY SCHOOL - CABADBARAN CITY | D6: PR No.: 2026-06-002 sbfp Q-2026-05-002 SBFP MEAT for SBFP 2026 | E6: Food Stuff | F6: CARAGA | G6: AGUSAN DEL NORTE | H6: 407930 | I6: 46181 | J6: 0.33333333 | K6: =IF(I12="","",I12-TODAY()) -> -11 | L6: Low | N6: Cancelled | O6: Cancelled by sir omar | R6: Cancelled | S6: =IF(H12="","",IFERROR(IF(H12>5000000,30,IF(H12>=1000000,20,10))+IF(I12-TODAY()>14,30,IF(I12-TODAY()>=7,20,10))+IF(R12="Won",40,IF(R12="Lost",10,20)),"")) -> 40 | T6: =IF(OR(H12="",I12=""),"",IF(AND(H12>5000000,I12-TODAY()>10),"🚨 FLAG","—")) -> — | U6: =IF(S12="","",IF(S12>=70,"✅ Highly Recommended",IF(S12>=50,"🔶 Consider","❌ Low Priority"))) -> ❌ Low Priority
A7: 46180 | B7: 13032498 | C7: CARAGA STATE UNIVERSITY - CABADBARAN CAMPUS | D7: PROVISION OF 2ND QUARTER OFFICE SUPPLIES FOR USE BY VARIOUS OFFICES, IGF-164-26-05-319 | E7: Office Supplies | F7: CARAGA | G7: AGUSAN DEL NORTE | H7: 386406.47 | I7: 46184 | J7: 0.33333333 | K7: =IF(I13="","",I13-TODAY()) -> -11 | L7: =IF(I13="","",IF(I13-TODAY()<=3,"High",IF(I13-TODAY()<=7,"Medium","Low"))) -> High | N7: Submitting | O7: For Checking by maam Astrid | R7: Pending | S7: =IF(H13="","",IFERROR(IF(H13>5000000,30,IF(H13>=1000000,20,10))+IF(I13-TODAY()>14,30,IF(I13-TODAY()>=7,20,10))+IF(R13="Won",40,IF(R13="Lost",10,20)),"")) -> 40 | T7: =IF(OR(H13="",I13=""),"",IF(AND(H13>5000000,I13-TODAY()>10),"🚨 FLAG","—")) -> — | U7: =IF(S13="","",IF(S13>=70,"✅ Highly Recommended",IF(S13>=50,"🔶 Consider","❌ Low Priority"))) -> 🔶 Consider
A8: 46180 | B8: 12994917 | C8: CARAGA REGIONAL HOSPITAL | D8: SUPPLY AND DELIVERY OF GREYSCALE PAPER A4 SIZE FOR CT SCAN OR XRAY | E8: Office Supplies | F8: CARAGA | G8: SURIGAO DEL NORTE | H8: 2400000 | I8: 46183 | J8: 0.41666667 | K8: =IF(I14="","",I14-TODAY()) -> -11 | L8: =IF(I14="","",IF(I14-TODAY()<=3,"High",IF(I14-TODAY()<=7,"Medium","Low"))) -> High | N8: Under Evaluation | O8: Under Evaluation | R8: Pending | S8: =IF(H14="","",IFERROR(IF(H14>5000000,30,IF(H14>=1000000,20,10))+IF(I14-TODAY()>14,30,IF(I14-TODAY()>=7,20,10))+IF(R14="Won",40,IF(R14="Lost",10,20)),"")) -> 40 | T8: =IF(OR(H14="",I14=""),"",IF(AND(H14>5000000,I14-TODAY()>10),"🚨 FLAG","—")) -> — | U8: =IF(S14="","",IF(S14>=70,"✅ Highly Recommended",IF(S14>=50,"🔶 Consider","❌ Low Priority"))) -> ❌ Low Priority
A9: 46179 | B9: 13029937 | C9: DEPARTMENT OF SOCIAL WELFARE AND DEVELOPMENT -CARAGA | D9: PURCHASE OF OFFICE SUPPLIES FOR JULY AND AUGUST FOR 4Ps USE | E9: Office Supplies | F9: CARAGA | G9: AGUSAN DEL NORTE | H9: 920450 | I9: 46181 | J9: 0.29166667 | K9: =IF(I4="","",I4-TODAY()) -> -10 | L9: =IF(I4="","",IF(I4-TODAY()<=3,"High",IF(I4-TODAY()<=7,"Medium","Low"))) -> High | M9: DAVEN | N9: Submitted | O9: Submitted by daven | P9: 46181 | R9: Pending | S9: =IF(H4="","",IFERROR(IF(H4>5000000,30,IF(H4>=1000000,20,10))+IF(I4-TODAY()>14,30,IF(I4-TODAY()>=7,20,10))+IF(R4="Won",40,IF(R4="Lost",10,20)),"")) -> 40 | T9: =IF(OR(H4="",I4=""),"",IF(AND(H4>5000000,I4-TODAY()>10),"🚨 FLAG","—")) -> — | U9: =IF(S4="","",IF(S4>=70,"✅ Highly Recommended",IF(S4>=50,"🔶 Consider","❌ Low Priority"))) -> ❌ Low Priority
A10: 46179 | B10: 13025115 | C10: DEPARTMENT OF SOCIAL WELFARE AND DEVELOPMENT -CARAGA | D10: SUBSIDIES EXPENSE: HFG RESIDENT'S SCHOOL SUPPLIES, CY 2026 | E10: Office Supplies | F10: CARAGA | G10: AGUSAN DEL NORTE | H10: 209927 | I10: 46181 | J10: 0.33333333 | K10: =IF(I5="","",I5-TODAY()) -> -12 | L10: =IF(I5="","",IF(I5-TODAY()<=3,"High",IF(I5-TODAY()<=7,"Medium","Low"))) -> High | M10: DAVEN | N10: Submitted | O10: Submitted by daven | P10: 46181 | R10: Pending | S10: =IF(H5="","",IFERROR(IF(H5>5000000,30,IF(H5>=1000000,20,10))+IF(I5-TODAY()>14,30,IF(I5-TODAY()>=7,20,10))+IF(R5="Won",40,IF(R5="Lost",10,20)),"")) -> 40 | T10: =IF(OR(H5="",I5=""),"",IF(AND(H5>5000000,I5-TODAY()>10),"🚨 FLAG","—")) -> — | U10: =IF(S5="","",IF(S5>=70,"✅ Highly Recommended",IF(S5>=50,"🔶 Consider","❌ Low Priority"))) -> ❌ Low Priority
A11: 46179 | B11: 13035898 | C11: DEPARTMENT OF HEALTH - CARAGA | D11: TOKEN AND AWARDS | E11: Tokens and Awards | F11: CARAGA | G11: AGUSAN DEL NORTE | H11: 330240 | I11: 46182 | J11: 0.625 | K11: =IF(I6="","",I6-TODAY()) -> -12 | L11: =IF(I6="","",IF(I6-TODAY()<=3,"High",IF(I6-TODAY()<=7,"Medium","Low"))) -> High | M11: Ann | N11: Submitted | O11: Submitted by daven | P11: 46181 | R11: Pending | S11: =IF(H6="","",IFERROR(IF(H6>5000000,30,IF(H6>=1000000,20,10))+IF(I6-TODAY()>14,30,IF(I6-TODAY()>=7,20,10))+IF(R6="Won",40,IF(R6="Lost",10,20)),"")) -> 40 | T11: =IF(OR(H6="",I6=""),"",IF(AND(H6>5000000,I6-TODAY()>10),"🚨 FLAG","—")) -> — | U11: =IF(S6="","",IF(S6>=70,"✅ Highly Recommended",IF(S6>=50,"🔶 Consider","❌ Low Priority"))) -> ❌ Low Priority
A12: 46179 | B12: 13036461 | C12: DEPARTMENT OF SOCIAL WELFARE AND DEVELOPMENT -CARAGA | D12: FOR PERSONNEL OFFICE USE | E12: IT Equipment | F12: CARAGA | G12: AGUSAN DEL NORTE | H12: 252995 | I12: 46182 | J12: 0.375 | K12: =IF(I7="","",I7-TODAY()) -> -9 | L12: Low | N12: Cancelled | O12: Cancelled by sir omar | R12: Cancelled | S12: =IF(H7="","",IFERROR(IF(H7>5000000,30,IF(H7>=1000000,20,10))+IF(I7-TODAY()>14,30,IF(I7-TODAY()>=7,20,10))+IF(R7="Won",40,IF(R7="Lost",10,20)),"")) -> 40 | T12: =IF(OR(H7="",I7=""),"",IF(AND(H7>5000000,I7-TODAY()>10),"🚨 FLAG","—")) -> — | U12: =IF(S7="","",IF(S7>=70,"✅ Highly Recommended",IF(S7>=50,"🔶 Consider","❌ Low Priority"))) -> ❌ Low Priority
A13: 46179 | B13: 13036211 | C13: DEPARTMENT OF AGRICULTURE - CARAGA | D13: POCUREMENT OF FARM TOOLS | E13: General Merchandise | F13: CARAGA | G13: AGUSAN DEL NORTE | H13: 501104 | I13: 46182 | J13: 0.041666667 | K13: =IF(I8="","",I8-TODAY()) -> -10 | L13: Low | N13: Cancelled | O13: Cancelled by sir omar | R13: Cancelled | S13: =IF(H8="","",IFERROR(IF(H8>5000000,30,IF(H8>=1000000,20,10))+IF(I8-TODAY()>14,30,IF(I8-TODAY()>=7,20,10))+IF(R8="Won",40,IF(R8="Lost",10,20)),"")) -> 50 | T13: =IF(OR(H8="",I8=""),"",IF(AND(H8>5000000,I8-TODAY()>10),"🚨 FLAG","—")) -> — | U13: =IF(S8="","",IF(S8>=70,"✅ Highly Recommended",IF(S8>=50,"🔶 Consider","❌ Low Priority"))) -> ❌ Low Priority
A14: 46179 | B14: 13037476 | C14: DEPARTMENT OF SOCIAL WELFARE AND DEVELOPMENT -CARAGA | D14: PURCHASE OF DESKTOP/LAPTOP/PRINTERS FRR HRMDD/HRPPMS USAGE | E14: IT Equipment | F14: CARAGA | G14: AGUSAN DEL NORTE | H14: 349993 | I14: 46182 | J14: 0.375 | K14: =IF(I9="","",I9-TODAY()) -> -12 | L14: Low | N14: Cancelled | O14: Cancelled by sir omar | R14: Cancelled | S14: =IF(H9="","",IFERROR(IF(H9>5000000,30,IF(H9>=1000000,20,10))+IF(I9-TODAY()>14,30,IF(I9-TODAY()>=7,20,10))+IF(R9="Won",40,IF(R9="Lost",10,20)),"")) -> 40 | T14: =IF(OR(H9="",I9=""),"",IF(AND(H9>5000000,I9-TODAY()>10),"🚨 FLAG","—")) -> — | U14: =IF(S9="","",IF(S9>=70,"✅ Highly Recommended",IF(S9>=50,"🔶 Consider","❌ Low Priority"))) -> ❌ Low Priority
A15: 46176 | B15: 13030274 | C15: DEPARTMENT OF SOCIAL WELFARE AND DEVELOPMENT -CARAGA | D15: PURCHASE OF OFFICE SUPPLIES FOR JULY AND AUGUST FOR 4Ps USE (INK CARTRIDGE) | E15: General Merchandise | F15: CARAGA | G15: AGUSAN DEL NORTE | H15: 571100 | I15: 46181 | J15: 0.29166667 | K15: =IF(I15="","",I15-TODAY()) -> -12 | L15: =IF(I15="","",IF(I15-TODAY()<=3,"High",IF(I15-TODAY()<=7,"Medium","Low"))) -> High | N15: Submitted | O15: Submitted by daven | P15: 46181 | R15: Pending | S15: =IF(H15="","",IFERROR(IF(H15>5000000,30,IF(H15>=1000000,20,10))+IF(I15-TODAY()>14,30,IF(I15-TODAY()>=7,20,10))+IF(R15="Won",40,IF(R15="Lost",10,20)),"")) -> 40 | T15: =IF(OR(H15="",I15=""),"",IF(AND(H15>5000000,I15-TODAY()>10),"🚨 FLAG","—")) -> — | U15: =IF(S15="","",IF(S15>=70,"✅ Highly Recommended",IF(S15>=50,"🔶 Consider","❌ Low Priority"))) -> ❌ Low Priority
A16: 46182 | B16: 13007679 | C16: DEPARTMENT OF EDUCATION - DIVISION OF SURIGAO DEL NORTE | D16: INVITATION TO BID FOR PROCUREMENT OF E-NUTRIBUN SQUASH VARIANT WITH 150 ML KALAMANSI JUICE, E-NUTRIBUN CARROT VARIANT WITH 150 ML KAMOTE JUICE, AND NUTRIBUNNETS WITH FILLING, WITH CERTIFICATION FROM D | E16: Food Stuff | F16: CARAGA | G16: SURIGAO DEL NORTE | H16: 3486560 | I16: 46184 | J16: 0.375 | K16: =IF(I16="","",I16-TODAY()) -> -9 | L16: =IF(I16="","",IF(I16-TODAY()<=3,"High",IF(I16-TODAY()<=7,"Medium","Low"))) -> High | N16: Cancelled | O16: FOR REVIEW | R16: Cancelled | S16: =IF(H16="","",IFERROR(IF(H16>5000000,30,IF(H16>=1000000,20,10))+IF(I16-TODAY()>14,30,IF(I16-TODAY()>=7,20,10))+IF(R16="Won",40,IF(R16="Lost",10,20)),"")) -> 50 | T16: =IF(OR(H16="",I16=""),"",IF(AND(H16>5000000,I16-TODAY()>10),"🚨 FLAG","—")) -> — | U16: =IF(S16="","",IF(S16>=70,"✅ Highly Recommended",IF(S16>=50,"🔶 Consider","❌ Low Priority"))) -> 🔶 Consider
A17: 46182 | B17: 13036941 | C17: DEPARTMENT OF AGRICULTURE - CARAGA | D17: Procurement of Animal Feeds (3 Lots) | E17: Animal Feeds | F17: CARAGA | G17: AGUSAN DEL NORTE | H17: 9866160 | I17: 46202 | J17: 0.375 | K17: =IF(I17="","",I17-TODAY()) -> 9 | L17: =IF(I17="","",IF(I17-TODAY()<=3,"High",IF(I17-TODAY()<=7,"Medium","Low"))) -> Low | N17: For Canvas | O17: FOR PRICING BY ZAR | R17: Pending | S17: =IF(H17="","",IFERROR(IF(H17>5000000,30,IF(H17>=1000000,20,10))+IF(I17-TODAY()>14,30,IF(I17-TODAY()>=7,20,10))+IF(R17="Won",40,IF(R17="Lost",10,20)),"")) -> 70 | T17: =IF(OR(H17="",I17=""),"",IF(AND(H17>5000000,I17-TODAY()>10),"🚨 FLAG","—")) -> — | U17: =IF(S17="","",IF(S17>=70,"✅ Highly Recommended",IF(S17>=50,"🔶 Consider","❌ Low Priority"))) -> ✅ Highly Recommended | V17: ..\..\..\..\..\..\..\..\..\Agencies\June 09, 2026\DA - CARAGA\Bidding Document.pdf
A18: 46184 | B18: 13047472 | C18: DEPARTMENT OF HEALTH - CARAGA | D18: TOKEN AND AWARDS | E18: Hygiene Kits | F18: CARAGA | G18: AGUSAN DEL NORTE | H18: 1500000 | I18: 46188 | J18: 0.625 | K18: =IF(I18="","",I18-TODAY()) -> -5 | L18: =IF(I18="","",IF(I18-TODAY()<=3,"High",IF(I18-TODAY()<=7,"Medium","Low"))) -> High | N18: For Canvas | O18: For canvass by Ann | R18: Pending | S18: =IF(H18="","",IFERROR(IF(H18>5000000,30,IF(H18>=1000000,20,10))+IF(I18-TODAY()>14,30,IF(I18-TODAY()>=7,20,10))+IF(R18="Won",40,IF(R18="Lost",10,20)),"")) -> 50 | T18: =IF(OR(H18="",I18=""),"",IF(AND(H18>5000000,I18-TODAY()>10),"🚨 FLAG","—")) -> — | U18: =IF(S18="","",IF(S18>=70,"✅ Highly Recommended",IF(S18>=50,"🔶 Consider","❌ Low Priority"))) -> 🔶 Consider | V18: E:\za\Agencies\June 11, 2026\DOH - Caraga\TOKEN AND AWARDS.pdf
A19: 46184 | B19: 13048712 | C19: DEPARTMENT OF PUBLIC WORKS AND HIGHWAYS - BUTUAN CITY DEO | D19: RFQ - 1 unit Desktop Computer (Application Use) and 6 unit Desktop Computer (Administrative Use) | E19: IT Equipment | F19: CARAGA | G19: AGUSAN DEL NORTE | H19: 1277131 | I19: 46188 | J19: 0.58333333 | K19: =IF(I19="","",I19-TODAY()) -> -5 | L19: =IF(I19="","",IF(I19-TODAY()<=3,"High",IF(I19-TODAY()<=7,"Medium","Low"))) -> High | N19: Pending | O19: For canvass by Zar | R19: Pending | S19: =IF(H19="","",IFERROR(IF(H19>5000000,30,IF(H19>=1000000,20,10))+IF(I19-TODAY()>14,30,IF(I19-TODAY()>=7,20,10))+IF(R19="Won",40,IF(R19="Lost",10,20)),"")) -> 50 | T19: =IF(OR(H19="",I19=""),"",IF(AND(H19>5000000,I19-TODAY()>10),"🚨 FLAG","—")) -> — | U19: =IF(S19="","",IF(S19>=70,"✅ Highly Recommended",IF(S19>=50,"🔶 Consider","❌ Low Priority"))) -> 🔶 Consider | V19: E:\za\Agencies\June 11, 2026\DPWH - Caraga\SPECS FOR PR NO. 2026-06-0105 DATED 06-02-2026.pdf
A20: 46184 | B20: 13042838 | C20: DEPARTMENT OF SCIENCE AND TECHNOLOGY - CARAGA (CSU-AMPAYON, BUTUAN CITY) | D20: Supply & delivery of 5-units Laptop with Complete Accessories | E20: IT Equipment | F20: CARAGA | G20: AGUSAN DEL NORTE | H20: 247500 | I20: 46189 | J20: 0.5 | K20: =IF(I20="","",I20-TODAY()) -> -4 | L20: =IF(I20="","",IF(I20-TODAY()<=3,"High",IF(I20-TODAY()<=7,"Medium","Low"))) -> High | N20: For Canvas | O20: For canvass by Zar | R20: Pending | S20: =IF(H20="","",IFERROR(IF(H20>5000000,30,IF(H20>=1000000,20,10))+IF(I20-TODAY()>14,30,IF(I20-TODAY()>=7,20,10))+IF(R20="Won",40,IF(R20="Lost",10,20)),"")) -> 40 | T20: =IF(OR(H20="",I20=""),"",IF(AND(H20>5000000,I20-TODAY()>10),"🚨 FLAG","—")) -> — | U20: =IF(S20="","",IF(S20>=70,"✅ Highly Recommended",IF(S20>=50,"🔶 Consider","❌ Low Priority"))) -> ❌ Low Priority | V20: E:\za\Agencies\June 11, 2026\DST - Caraga\Request for Quotation-LAPTOP.pdf
A21: 46184 | B21: 13051917 | C21: DEPARTMENT OF SOCIAL WELFARE AND DEVELOPMENT - CARAGA | D21: Procurement of Printers and Document Scanners for 4Ps use. | E21: IT Equipment | F21: CARAGA | G21: AGUSAN DEL NORTE | H21: 253000 | I21: 46190 | J21: 0.29166667 | K21: =IF(I21="","",I21-TODAY()) -> -3 | L21: =IF(I21="","",IF(I21-TODAY()<=3,"High",IF(I21-TODAY()<=7,"Medium","Low"))) -> High | N21: For Request Docs | O21: Requesting Documents | R21: Pending | S21: =IF(H21="","",IFERROR(IF(H21>5000000,30,IF(H21>=1000000,20,10))+IF(I21-TODAY()>14,30,IF(I21-TODAY()>=7,20,10))+IF(R21="Won",40,IF(R21="Lost",10,20)),"")) -> 40 | T21: =IF(OR(H21="",I21=""),"",IF(AND(H21>5000000,I21-TODAY()>10),"🚨 FLAG","—")) -> — | U21: =IF(S21="","",IF(S21>=70,"✅ Highly Recommended",IF(S21>=50,"🔶 Consider","❌ Low Priority"))) -> ❌ Low Priority | V21: REQUESTING A DOCUMENT TO DSWD
A22: 46184 | B22: 13045199 | C22: DEPARTMENT OF SOCIAL WELFARE AND DEVELOPMENT - CARAGA | D22: Subsidies Expense: HFG Residents' Apparel and Lines School Supplies Use CY 2026 | E22: General Merchandise | F22: CARAGA | G22: AGUSAN DEL NORTE | H22: 324200 | I22: 46188 | J22: 0.33333333 | K22: =IF(I22="","",I22-TODAY()) -> -5 | L22: =IF(I22="","",IF(I22-TODAY()<=3,"High",IF(I22-TODAY()<=7,"Medium","Low"))) -> High | N22: Submitting | O22: Submitting by daven | P22: 46188 | R22: Pending | S22: =IF(H22="","",IFERROR(IF(H22>5000000,30,IF(H22>=1000000,20,10))+IF(I22-TODAY()>14,30,IF(I22-TODAY()>=7,20,10))+IF(R22="Won",40,IF(R22="Lost",10,20)),"")) -> 40 | T22: =IF(OR(H22="",I22=""),"",IF(AND(H22>5000000,I22-TODAY()>10),"🚨 FLAG","—")) -> — | U22: =IF(S22="","",IF(S22>=70,"✅ Highly Recommended",IF(S22>=50,"🔶 Consider","❌ Low Priority"))) -> ❌ Low Priority | V22: E:\za\Agencies\June 11, 2026\DSWD - Caraga\Request for Quotation.pdf
A23: 46179 | B23: 13042045 | C23: DEPARTMENT OF SOCIAL WELFARE AND DEVELOPMENT - CARAGA | D23: SUPPLY AND DELIVERY OF VARIOUS FOOD ITEMS FOR SUPPLEMENTARY FEEDING PROGRAM IMPLEMENTATION FOR C.Y. 2026 (16th CYCLE)–ALTERNATIVE MEALS FOR DSWD FO CARAGA UNDER NP-TWO FAILED BIDDINGS-2ND POSTING | E23: Food Stuff | F23: CARAGA | G23: AGUSAN DEL NORTE | H23: 67713600 | I23: 46189 | J23: 0.375 | K23: =IF(I23="","",I23-TODAY()) -> -4 | L23: =IF(I23="","",IF(I23-TODAY()<=3,"High",IF(I23-TODAY()<=7,"Medium","Low"))) -> High | N23: Cancelled | O23: Cancelled by sir omar & ma'am Astrid | R23: Cancelled | S23: =IF(H23="","",IFERROR(IF(H23>5000000,30,IF(H23>=1000000,20,10))+IF(I23-TODAY()>14,30,IF(I23-TODAY()>=7,20,10))+IF(R23="Won",40,IF(R23="Lost",10,20)),"")) -> 60 | T23: =IF(OR(H23="",I23=""),"",IF(AND(H23>5000000,I23-TODAY()>10),"🚨 FLAG","—")) -> — | U23: =IF(S23="","",IF(S23>=70,"✅ Highly Recommended",IF(S23>=50,"🔶 Consider","❌ Low Priority"))) -> 🔶 Consider | V23: C:\Users\admin\Desktop\BHM-PhilGeps\Agencies\June 11, 2026\DSWD_1 - Caraga\NP- TWO FAILED BIDDING - NEGOTIATION DOCUMENT.pdf
A24: 46184 | B24: 13050778 | C24: NORTH EASTERN MINDANAO STATE UNIVERSITY | D24: Supply and Delivery of Information Technology (ICT Equipment) for DHM Faculty and Staff usage of NEMSU Tandag Campus. | E24: IT Equipment | F24: CARAGA | G24: Surigao Del Sur | H24: 230000 | I24: 46188 | J24: 0.41666667 | K24: =IF(I24="","",I24-TODAY()) -> -5 | L24: =IF(I24="","",IF(I24-TODAY()<=3,"High",IF(I24-TODAY()<=7,"Medium","Low"))) -> High | N24: For Canvas | O24: For canvass by Zar | R24: Pending | S24: =IF(H24="","",IFERROR(IF(H24>5000000,30,IF(H24>=1000000,20,10))+IF(I24-TODAY()>14,30,IF(I24-TODAY()>=7,20,10))+IF(R24="Won",40,IF(R24="Lost",10,20)),"")) -> 40 | T24: =IF(OR(H24="",I24=""),"",IF(AND(H24>5000000,I24-TODAY()>10),"🚨 FLAG","—")) -> — | U24: =IF(S24="","",IF(S24>=70,"✅ Highly Recommended",IF(S24>=50,"🔶 Consider","❌ Low Priority"))) -> ❌ Low Priority | V24: C:\Users\admin\Desktop\BHM-PhilGeps\Agencies\June 11, 2026\NEMSU Tandag Campus\RFQ.pdf
A25: 46184 | B25: 13048298 | C25: NORTH EASTERN MINDANAO STATE UNIVERSITY | D25: Supply and Delivery of ICT Equipment & Supplies for ICT Computer and Network Supply and Maintenance use of NEMSU Tandag Campus. | E25: IT Equipment | F25: CARAGA | G25: Surigao Del Sur | H25: 1580332.4 | I25: 46188 | J25: 0.41666667 | K25: =IF(I25="","",I25-TODAY()) -> -5 | L25: =IF(I25="","",IF(I25-TODAY()<=3,"High",IF(I25-TODAY()<=7,"Medium","Low"))) -> High | N25: For Canvas | O25: For canvass by Zar | R25: Pending | S25: =IF(H25="","",IFERROR(IF(H25>5000000,30,IF(H25>=1000000,20,10))+IF(I25-TODAY()>14,30,IF(I25-TODAY()>=7,20,10))+IF(R25="Won",40,IF(R25="Lost",10,20)),"")) -> 50 | T25: =IF(OR(H25="",I25=""),"",IF(AND(H25>5000000,I25-TODAY()>10),"🚨 FLAG","—")) -> — | U25: =IF(S25="","",IF(S25>=70,"✅ Highly Recommended",IF(S25>=50,"🔶 Consider","❌ Low Priority"))) -> 🔶 Consider | V25: C:\Users\admin\Desktop\BHM-PhilGeps\Agencies\June 11, 2026\NEMSU Tandag Campus - 1\RFQ.pdf
A26: 46187 | B26: 13031492 | C26: DEPARTMENT OF SOCIAL WELFARE AND DEVELOPMENT - CARAGA | D26: PROCUREMENT OF VARIOUS FOOD ITEMS FOR SUPPLEMENTARY FEEDING PROGRAM IMPLEMENTATION FOR C.Y. 2026 (16th CYCLE) – ALTERNATIVE MEALS FOR DSWD FIELD OFFICE CARAGA – SIARGAO ISLAND | E26: Food Stuff | F26: CARAGA | G26: AGUSAN DEL NORTE | H26: 3906000 | I26: 46196 | J26: 0.5 | K26: =IF(I26="","",I26-TODAY()) -> 3 | L26: =IF(I26="","",IF(I26-TODAY()<=3,"High",IF(I26-TODAY()<=7,"Medium","Low"))) -> High | N26: For Review | O26: FOR REVIEW BY SIR OMAR | R26: Pending | S26: =IF(H26="","",IFERROR(IF(H26>5000000,30,IF(H26>=1000000,20,10))+IF(I26-TODAY()>14,30,IF(I26-TODAY()>=7,20,10))+IF(R26="Won",40,IF(R26="Lost",10,20)),"")) -> 50 | T26: =IF(OR(H26="",I26=""),"",IF(AND(H26>5000000,I26-TODAY()>10),"🚨 FLAG","—")) -> — | U26: =IF(S26="","",IF(S26>=70,"✅ Highly Recommended",IF(S26>=50,"🔶 Consider","❌ Low Priority"))) -> 🔶 Consider | V26: ..\..\..\..\..\..\..\..\..\Agencies\June 14, 2026\DSWD - CARAGA\BIDDING DOCUMENTS.pdf
A27: 46187 | B27: 36729 | C27: PATIN-AY NATIONAL HIGH SCHOOL - Agusan Del Sur | D27: Procurement of Office Supplies and Materials in the Conduct of PPST-Based and PPSSH-Based PD Program: Training on the Strengthened Senior High School Curriculum (DepEd-Division Office) | E27: Office Supplies | F27: CARAGA | G27: AGUSAN DEL SUR | H27: 267965 | I27: 46190 | J27: 0.375 | K27: =IF(I27="","",I27-TODAY()) -> -3 | L27: =IF(I27="","",IF(I27-TODAY()<=3,"High",IF(I27-TODAY()<=7,"Medium","Low"))) -> High | N27: For Review | O27: FOR REVIEW BY ROTCHE | R27: Pending | S27: =IF(H27="","",IFERROR(IF(H27>5000000,30,IF(H27>=1000000,20,10))+IF(I27-TODAY()>14,30,IF(I27-TODAY()>=7,20,10))+IF(R27="Won",40,IF(R27="Lost",10,20)),"")) -> 40 | T27: =IF(OR(H27="",I27=""),"",IF(AND(H27>5000000,I27-TODAY()>10),"🚨 FLAG","—")) -> — | U27: =IF(S27="","",IF(S27>=70,"✅ Highly Recommended",IF(S27>=50,"🔶 Consider","❌ Low Priority"))) -> ❌ Low Priority | V27: ..\..\..\..\..\..\..\..\..\Agencies\June 14, 2026\DEPED - CARAGA\1781328153_2026_06_0245_Supplies_Jalalon.pdf
A28: 46187 | B28: 13042259 | C28: DEPARTMENT OF SOCIAL WELFARE AND DEVELOPMENT - CARAGA | D28: SUPPLY AND DELIVERY OF VARIOUS FOOD ITEMS FOR SFP IMPLEMENTATION FOR C.Y. 2026 (16th CYCLE)-HOTMEALS FOR BACUAG, CLAVER, GIGAQUIT AND PLACER SDN UNDER NP-TWO FAILED BIDDING-2ND POSTING | E28: Food Stuff | F28: CARAGA | G28: AGUSAN DEL NORTE | H28: 4590000 | I28: 46189 | J28: 0.375 | K28: =IF(I28="","",I28-TODAY()) -> -4 | L28: =IF(I28="","",IF(I28-TODAY()<=3,"High",IF(I28-TODAY()<=7,"Medium","Low"))) -> High | N28: Under Evaluation | O28: FOR EVALUATION | R28: Pending | S28: =IF(H28="","",IFERROR(IF(H28>5000000,30,IF(H28>=1000000,20,10))+IF(I28-TODAY()>14,30,IF(I28-TODAY()>=7,20,10))+IF(R28="Won",40,IF(R28="Lost",10,20)),"")) -> 50 | T28: =IF(OR(H28="",I28=""),"",IF(AND(H28>5000000,I28-TODAY()>10),"🚨 FLAG","—")) -> — | U28: =IF(S28="","",IF(S28>=70,"✅ Highly Recommended",IF(S28>=50,"🔶 Consider","❌ Low Priority"))) -> 🔶 Consider | V28: ..\..\..\..\..\..\..\..\..\Agencies\June 14, 2026\DSWD_BACUAG- CARAGA\NP- TWO FAILED BIDDING - NEGOTIATION DOCUMENT.pdf
A29: 46190 | B29: 13061414 | C29: CARAGA STATE UNIVERSITY | D29: RFQ - PROVISION OF OFFICE AND OTHER SUPPLIES AND MATERIALS FOR THE VARIOUS CSU ADMINISTRATIVE OFFICE OPERATIONS. , RAF-101-26-06-355 | E29: Office Supplies | F29: CARAGA | G29: AGUSAN DEL NORTE | H29: 238587.3 | I29: 46195 | J29: 0.33333333 | K29: =IF(I29="","",I29-TODAY()) -> 2 | L29: =IF(I29="","",IF(I29-TODAY()<=3,"High",IF(I29-TODAY()<=7,"Medium","Low"))) -> High | N29: For Review | O29: FOR REVIEW BY SIR OMAR | R29: Pending | S29: =IF(H29="","",IFERROR(IF(H29>5000000,30,IF(H29>=1000000,20,10))+IF(I29-TODAY()>14,30,IF(I29-TODAY()>=7,20,10))+IF(R29="Won",40,IF(R29="Lost",10,20)),"")) -> 40 | T29: =IF(OR(H29="",I29=""),"",IF(AND(H29>5000000,I29-TODAY()>10),"🚨 FLAG","—")) -> — | U29: =IF(S29="","",IF(S29>=70,"✅ Highly Recommended",IF(S29>=50,"🔶 Consider","❌ Low Priority"))) -> ❌ Low Priority | V29: ..\..\..\..\..\..\..\..\..\Agencies\JUNE 17, 2026\CSU - CARAGA\Canvass Form.pdf
A30: 46191 | B30: 13046873 | C30: NORTH CABADBARAN CENTRAL ELEMENTARY SCHOOL - CABADBARAN CITY | D30: Grocery Items | E30: Food Stuff | F30: CARAGA | G30: AGUSAN DEL NORTE | H30: 412634 | I30: 46195 | J30: 0.041666667 | K30: =IF(I30="","",I30-TODAY()) -> 2 | L30: =IF(I30="","",IF(I30-TODAY()<=3,"High",IF(I30-TODAY()<=7,"Medium","Low"))) -> High | N30: Submitting | O30: Submitting by daven | R30: Pending | S30: =IF(H30="","",IFERROR(IF(H30>5000000,30,IF(H30>=1000000,20,10))+IF(I30-TODAY()>14,30,IF(I30-TODAY()>=7,20,10))+IF(R30="Won",40,IF(R30="Lost",10,20)),"")) -> 40 | T30: =IF(OR(H30="",I30=""),"",IF(AND(H30>5000000,I30-TODAY()>10),"🚨 FLAG","—")) -> — | U30: =IF(S30="","",IF(S30>=70,"✅ Highly Recommended",IF(S30>=50,"🔶 Consider","❌ Low Priority"))) -> ❌ Low Priority | V30: ..\..\..\..\..\..\..\..\..\Agencies\June 18, 2026\Cabadbaran Elem\Grocery Items.pdf
A31: 46191 | B31: 13046956 | C31: NORTH CABADBARAN CENTRAL ELEMENTARY SCHOOL - CABADBARAN CITY | D31: Grocery Items | E31: Food Stuff | F31: CARAGA | G31: AGUSAN DEL NORTE | H31: 487550 | I31: 46195 | J31: 0.041666667 | K31: =IF(I31="","",I31-TODAY()) -> 2 | L31: =IF(I31="","",IF(I31-TODAY()<=3,"High",IF(I31-TODAY()<=7,"Medium","Low"))) -> High | N31: Submitting | O31: Submitting by daven | R31: Pending | S31: =IF(H31="","",IFERROR(IF(H31>5000000,30,IF(H31>=1000000,20,10))+IF(I31-TODAY()>14,30,IF(I31-TODAY()>=7,20,10))+IF(R31="Won",40,IF(R31="Lost",10,20)),"")) -> 40 | T31: =IF(OR(H31="",I31=""),"",IF(AND(H31>5000000,I31-TODAY()>10),"🚨 FLAG","—")) -> — | U31: =IF(S31="","",IF(S31>=70,"✅ Highly Recommended",IF(S31>=50,"🔶 Consider","❌ Low Priority"))) -> ❌ Low Priority | V31: C:\Users\admin\Desktop\BHM-PhilGeps\Agencies\June 18, 2026\DEPED - CBR_FISH\Grocery Items - fish.pdf
A32: 46191 | B32: 13046969 | C32: NORTH CABADBARAN CENTRAL ELEMENTARY SCHOOL - CABADBARAN CITY | D32: Grocery Items - Fish | E32: Food Stuff | F32: CARAGA | G32: AGUSAN DEL NORTE | H32: 303000 | I32: 46195 | J32: 0.041666667 | K32: =IF(I32="","",I32-TODAY()) -> 2 | L32: =IF(I32="","",IF(I32-TODAY()<=3,"High",IF(I32-TODAY()<=7,"Medium","Low"))) -> High | N32: Submitting | O32: Submitting by daven | R32: Pending | S32: =IF(H32="","",IFERROR(IF(H32>5000000,30,IF(H32>=1000000,20,10))+IF(I32-TODAY()>14,30,IF(I32-TODAY()>=7,20,10))+IF(R32="Won",40,IF(R32="Lost",10,20)),"")) -> 40 | T32: =IF(OR(H32="",I32=""),"",IF(AND(H32>5000000,I32-TODAY()>10),"🚨 FLAG","—")) -> — | U32: =IF(S32="","",IF(S32>=70,"✅ Highly Recommended",IF(S32>=50,"🔶 Consider","❌ Low Priority"))) -> ❌ Low Priority | V32: C:\Users\admin\Desktop\BHM-PhilGeps\Agencies\June 18, 2026\DEPED - CBR_FISH\Grocery Items - fish.pdf
A33: 46193 | B33: 13062125 | C33: DEPARTMENT OF HEALTH - CARAGA | D33: Computer Consumables | E33: Inks | F33: CARAGA | G33: AGUSAN DEL NORTE | H33: 228600 | I33: 46195 | J33: 0.625 | K33: =IF(I33="","",I33-TODAY()) -> 2 | L33: =IF(I33="","",IF(I33-TODAY()<=3,"High",IF(I33-TODAY()<=7,"Medium","Low"))) -> High | N33: For Canvas | O33: For canvass by Ann | R33: Pending | S33: =IF(H33="","",IFERROR(IF(H33>5000000,30,IF(H33>=1000000,20,10))+IF(I33-TODAY()>14,30,IF(I33-TODAY()>=7,20,10))+IF(R33="Won",40,IF(R33="Lost",10,20)),"")) -> 40 | T33: =IF(OR(H33="",I33=""),"",IF(AND(H33>5000000,I33-TODAY()>10),"🚨 FLAG","—")) -> — | U33: =IF(S33="","",IF(S33>=70,"✅ Highly Recommended",IF(S33>=50,"🔶 Consider","❌ Low Priority"))) -> ❌ Low Priority | V33: C:\Users\admin\Desktop\PHILGEPS\13062125.pdf
A34: 46193 | B34: 13061994 | C34: DEPARTMENT OF HEALTH - CARAGA | D34: Office Supplies | E34: Office Supplies | F34: CARAGA | G34: AGUSAN DEL NORTE | H34: 453964.84 | I34: 46195 | J34: 0.625 | K34: =IF(I34="","",I34-TODAY()) -> 2 | L34: =IF(I34="","",IF(I34-TODAY()<=3,"High",IF(I34-TODAY()<=7,"Medium","Low"))) -> High | N34: For Checking | O34: For Checking by maam Astrid | R34: Pending | S34: =IF(H34="","",IFERROR(IF(H34>5000000,30,IF(H34>=1000000,20,10))+IF(I34-TODAY()>14,30,IF(I34-TODAY()>=7,20,10))+IF(R34="Won",40,IF(R34="Lost",10,20)),"")) -> 40 | T34: =IF(OR(H34="",I34=""),"",IF(AND(H34>5000000,I34-TODAY()>10),"🚨 FLAG","—")) -> — | U34: =IF(S34="","",IF(S34>=70,"✅ Highly Recommended",IF(S34>=50,"🔶 Consider","❌ Low Priority"))) -> ❌ Low Priority | V34: C:\Users\admin\Desktop\PHILGEPS\13061994.pdf
K35: =IF(I35="","",I35-TODAY()) | L35: =IF(I35="","",IF(I35-TODAY()<=3,"High",IF(I35-TODAY()<=7,"Medium","Low"))) | S35: =IF(H35="","",IFERROR(IF(H35>5000000,30,IF(H35>=1000000,20,10))+IF(I35-TODAY()>14,30,IF(I35-TODAY()>=7,20,10))+IF(R35="Won",40,IF(R35="Lost",10,20)),"")) | T35: =IF(OR(H35="",I35=""),"",IF(AND(H35>5000000,I35-TODAY()>10),"🚨 FLAG","—")) | U35: =IF(S35="","",IF(S35>=70,"✅ Highly Recommended",IF(S35>=50,"🔶 Consider","❌ Low Priority")))
K36: =IF(I36="","",I36-TODAY()) | L36: =IF(I36="","",IF(I36-TODAY()<=3,"High",IF(I36-TODAY()<=7,"Medium","Low"))) | S36: =IF(H36="","",IFERROR(IF(H36>5000000,30,IF(H36>=1000000,20,10))+IF(I36-TODAY()>14,30,IF(I36-TODAY()>=7,20,10))+IF(R36="Won",40,IF(R36="Lost",10,20)),"")) | T36: =IF(OR(H36="",I36=""),"",IF(AND(H36>5000000,I36-TODAY()>10),"🚨 FLAG","—")) | U36: =IF(S36="","",IF(S36>=70,"✅ Highly Recommended",IF(S36>=50,"🔶 Consider","❌ Low Priority")))
K37: =IF(I37="","",I37-TODAY()) | L37: =IF(I37="","",IF(I37-TODAY()<=3,"High",IF(I37-TODAY()<=7,"Medium","Low"))) | S37: =IF(H37="","",IFERROR(IF(H37>5000000,30,IF(H37>=1000000,20,10))+IF(I37-TODAY()>14,30,IF(I37-TODAY()>=7,20,10))+IF(R37="Won",40,IF(R37="Lost",10,20)),"")) | T37: =IF(OR(H37="",I37=""),"",IF(AND(H37>5000000,I37-TODAY()>10),"🚨 FLAG","—")) | U37: =IF(S37="","",IF(S37>=70,"✅ Highly Recommended",IF(S37>=50,"🔶 Consider","❌ Low Priority")))
K38: =IF(I38="","",I38-TODAY()) | L38: =IF(I38="","",IF(I38-TODAY()<=3,"High",IF(I38-TODAY()<=7,"Medium","Low"))) | S38: =IF(H38="","",IFERROR(IF(H38>5000000,30,IF(H38>=1000000,20,10))+IF(I38-TODAY()>14,30,IF(I38-TODAY()>=7,20,10))+IF(R38="Won",40,IF(R38="Lost",10,20)),"")) | T38: =IF(OR(H38="",I38=""),"",IF(AND(H38>5000000,I38-TODAY()>10),"🚨 FLAG","—")) | U38: =IF(S38="","",IF(S38>=70,"✅ Highly Recommended",IF(S38>=50,"🔶 Consider","❌ Low Priority")))
K39: =IF(I39="","",I39-TODAY()) | L39: =IF(I39="","",IF(I39-TODAY()<=3,"High",IF(I39-TODAY()<=7,"Medium","Low"))) | S39: =IF(H39="","",IFERROR(IF(H39>5000000,30,IF(H39>=1000000,20,10))+IF(I39-TODAY()>14,30,IF(I39-TODAY()>=7,20,10))+IF(R39="Won",40,IF(R39="Lost",10,20)),"")) | T39: =IF(OR(H39="",I39=""),"",IF(AND(H39>5000000,I39-TODAY()>10),"🚨 FLAG","—")) | U39: =IF(S39="","",IF(S39>=70,"✅ Highly Recommended",IF(S39>=50,"🔶 Consider","❌ Low Priority")))
K40: =IF(I40="","",I40-TODAY()) | L40: =IF(I40="","",IF(I40-TODAY()<=3,"High",IF(I40-TODAY()<=7,"Medium","Low"))) | S40: =IF(H40="","",IFERROR(IF(H40>5000000,30,IF(H40>=1000000,20,10))+IF(I40-TODAY()>14,30,IF(I40-TODAY()>=7,20,10))+IF(R40="Won",40,IF(R40="Lost",10,20)),"")) | T40: =IF(OR(H40="",I40=""),"",IF(AND(H40>5000000,I40-TODAY()>10),"🚨 FLAG","—")) | U40: =IF(S40="","",IF(S40>=70,"✅ Highly Recommended",IF(S40>=50,"🔶 Consider","❌ Low Priority")))
...

Sheet Search & Filter
A1: 🔍 SEARCH & FILTER — PhilGEPS Bid Monitoring
A2: ℹ️ Select filters below using the dropdowns. The results table and summary cards update automatically based on your selection.
B3: STATUS FILTER | C3: PRIORITY FILTER | D3: REGION FILTER | E3: CATEGORY FILTER | F3: RESULT FILTER
B4: All | C4: All | D4: All | E4: Other | F4: All
A6: 📊 FILTERED RESULTS SUMMARY
A7: 🔍 | C7: 💰 | E7: 🔥 | G7: 📤 | I7: 🏆
A8: MATCHING BIDS | C8: TOTAL ABC VALUE | E8: ACTIVE / URGENT | G8: SUBMITTED | I8: AWARDED / WON
A9: =IFERROR(COUNTIFS('Bid Monitoring'!B3:B200,"<>",'Bid Monitoring'!N3:N200,IF(B4="All","*",B4),'Bid Monitoring'!L3:L200,IF(C4="All","<>""",C4),'Bid Monitoring'!F3:F200,IF(D4="All","*",D4),'Bid Monitoring'!E3:E200,IF(E4="All","*",E4),'Bid Monitoring'!R3:R200,IF(F4="All","*",F4)),0) -> 0 | C9: =IFERROR(SUMPRODUCT(('Bid Monitoring'!B3:B200<>"")*(IF(B4="All",1,'Bid Monitoring'!N3:N200=B4))*(IF(C4="All",1,'Bid Monitoring'!L3:L200=C4))*(IF(D4="All",1,'Bid Monitoring'!F3:F200=D4))*(IF(E4="All",1,'Bid Monitoring'!E3:E200=E4))*(IF(F4="All",1,'Bid Monitoring'!R3:R200=F4))*'Bid Monitoring'!H3:H200),0) -> 0 | E9: =IFERROR(COUNTIFS('Bid Monitoring'!B3:B200,"<>",'Bid Monitoring'!N3:N200,IF(B4="All","*",B4),'Bid Monitoring'!L3:L200,IF(C4="All","<>""",C4),'Bid Monitoring'!F3:F200,IF(D4="All","*",D4),'Bid Monitoring'!E3:E200,IF(E4="All","*",E4),'Bid Monitoring'!R3:R200,IF(F4="All","*",F4),'Bid Monitoring'!L3:L200,"High"),0) -> 0 | G9: =IFERROR(COUNTIFS('Bid Monitoring'!B3:B200,"<>",'Bid Monitoring'!N3:N200,IF(B4="All","*",B4),'Bid Monitoring'!L3:L200,IF(C4="All","<>""",C4),'Bid Monitoring'!F3:F200,IF(D4="All","*",D4),'Bid Monitoring'!E3:E200,IF(E4="All","*",E4),'Bid Monitoring'!R3:R200,IF(F4="All","*",F4),'Bid Monitoring'!N3:N200,"Submitted"),0) -> 0 | I9: =IFERROR(COUNTIFS('Bid Monitoring'!B3:B200,"<>",'Bid Monitoring'!N3:N200,IF(B4="All","*",B4),'Bid Monitoring'!L3:L200,IF(C4="All","<>""",C4),'Bid Monitoring'!F3:F200,IF(D4="All","*",D4),'Bid Monitoring'!E3:E200,IF(E4="All","*",E4),'Bid Monitoring'!R3:R200,IF(F4="All","*",F4),'Bid Monitoring'!N3:N200,"Awarded"),0) -> 0
A11: 📋 FILTERED BID LIST (All matching rows shown below)
A12: Ref # | B12: Project Title | C12: Procuring Entity | D12: Category | E12: Region | F12: ABC (₱) | G12: Closing Date | H12: Days Left | I12: Status | J12: Priority
A13: =IF(AND('Bid Monitoring'!B3<>"",IF(B4="All",TRUE(),'Bid Monitoring'!N3=B4),IF(C4="All",TRUE(),'Bid Monitoring'!L3=C4),IF(D4="All",TRUE(),'Bid Monitoring'!F3=D4),IF(E4="All",TRUE(),'Bid Monitoring'!E3=E4),IF(F4="All",TRUE(),'Bid Monitoring'!R3=F4)),'Bid Monitoring'!B3,"") | B13: =IF(AND('Bid Monitoring'!B3<>"",IF(B4="All",TRUE(),'Bid Monitoring'!N3=B4),IF(C4="All",TRUE(),'Bid Monitoring'!L3=C4),IF(D4="All",TRUE(),'Bid Monitoring'!F3=D4),IF(E4="All",TRUE(),'Bid Monitoring'!E3=E4),IF(F4="All",TRUE(),'Bid Monitoring'!R3=F4)),'Bid Monitoring'!D3,"") | C13: =IF(AND('Bid Monitoring'!B3<>"",IF(B4="All",TRUE(),'Bid Monitoring'!N3=B4),IF(C4="All",TRUE(),'Bid Monitoring'!L3=C4),IF(D4="All",TRUE(),'Bid Monitoring'!F3=D4),IF(E4="All",TRUE(),'Bid Monitoring'!E3=E4),IF(F4="All",TRUE(),'Bid Monitoring'!R3=F4)),'Bid Monitoring'!C3,"") | D13: =IF(AND('Bid Monitoring'!B3<>"",IF(B4="All",TRUE(),'Bid Monitoring'!N3=B4),IF(C4="All",TRUE(),'Bid Monitoring'!L3=C4),IF(D4="All",TRUE(),'Bid Monitoring'!F3=D4),IF(E4="All",TRUE(),'Bid Monitoring'!E3=E4),IF(F4="All",TRUE(),'Bid Monitoring'!R3=F4)),'Bid Monitoring'!E3,"") | E13: =IF(AND('Bid Monitoring'!B3<>"",IF(B4="All",TRUE(),'Bid Monitoring'!N3=B4),IF(C4="All",TRUE(),'Bid Monitoring'!L3=C4),IF(D4="All",TRUE(),'Bid Monitoring'!F3=D4),IF(E4="All",TRUE(),'Bid Monitoring'!E3=E4),IF(F4="All",TRUE(),'Bid Monitoring'!R3=F4)),'Bid Monitoring'!F3,"") | F13: =IF(AND('Bid Monitoring'!B3<>"",IF(B4="All",TRUE(),'Bid Monitoring'!N3=B4),IF(C4="All",TRUE(),'Bid Monitoring'!L3=C4),IF(D4="All",TRUE(),'Bid Monitoring'!F3=D4),IF(E4="All",TRUE(),'Bid Monitoring'!E3=E4),IF(F4="All",TRUE(),'Bid Monitoring'!R3=F4)),'Bid Monitoring'!H3,"") | G13: =IF(AND('Bid Monitoring'!B3<>"",IF(B4="All",TRUE(),'Bid Monitoring'!N3=B4),IF(C4="All",TRUE(),'Bid Monitoring'!L3=C4),IF(D4="All",TRUE(),'Bid Monitoring'!F3=D4),IF(E4="All",TRUE(),'Bid Monitoring'!E3=E4),IF(F4="All",TRUE(),'Bid Monitoring'!R3=F4)),'Bid Monitoring'!I3,"") | H13: =IF(AND('Bid Monitoring'!B3<>"",IF(B4="All",TRUE(),'Bid Monitoring'!N3=B4),IF(C4="All",TRUE(),'Bid Monitoring'!L3=C4),IF(D4="All",TRUE(),'Bid Monitoring'!F3=D4),IF(E4="All",TRUE(),'Bid Monitoring'!E3=E4),IF(F4="All",TRUE(),'Bid Monitoring'!R3=F4)),'Bid Monitoring'!K3,"") | I13: =IF(AND('Bid Monitoring'!B3<>"",IF(B4="All",TRUE(),'Bid Monitoring'!N3=B4),IF(C4="All",TRUE(),'Bid Monitoring'!L3=C4),IF(D4="All",TRUE(),'Bid Monitoring'!F3=D4),IF(E4="All",TRUE(),'Bid Monitoring'!E3=E4),IF(F4="All",TRUE(),'Bid Monitoring'!R3=F4)),'Bid Monitoring'!N3,"") | J13: =IF(AND('Bid Monitoring'!B3<>"",IF(B4="All",TRUE(),'Bid Monitoring'!N3=B4),IF(C4="All",TRUE(),'Bid Monitoring'!L3=C4),IF(D4="All",TRUE(),'Bid Monitoring'!F3=D4),IF(E4="All",TRUE(),'Bid Monitoring'!E3=E4),IF(F4="All",TRUE(),'Bid Monitoring'!R3=F4)),'Bid Monitoring'!L3,"")
A14: =IF(AND('Bid Monitoring'!B4<>"",IF(B4="All",TRUE(),'Bid Monitoring'!N4=B4),IF(C4="All",TRUE(),'Bid Monitoring'!L4=C4),IF(D4="All",TRUE(),'Bid Monitoring'!F4=D4),IF(E4="All",TRUE(),'Bid Monitoring'!E4=E4),IF(F4="All",TRUE(),'Bid Monitoring'!R4=F4)),'Bid Monitoring'!B4,"") | B14: =IF(AND('Bid Monitoring'!B4<>"",IF(B4="All",TRUE(),'Bid Monitoring'!N4=B4),IF(C4="All",TRUE(),'Bid Monitoring'!L4=C4),IF(D4="All",TRUE(),'Bid Monitoring'!F4=D4),IF(E4="All",TRUE(),'Bid Monitoring'!E4=E4),IF(F4="All",TRUE(),'Bid Monitoring'!R4=F4)),'Bid Monitoring'!D4,"") | C14: =IF(AND('Bid Monitoring'!B4<>"",IF(B4="All",TRUE(),'Bid Monitoring'!N4=B4),IF(C4="All",TRUE(),'Bid Monitoring'!L4=C4),IF(D4="All",TRUE(),'Bid Monitoring'!F4=D4),IF(E4="All",TRUE(),'Bid Monitoring'!E4=E4),IF(F4="All",TRUE(),'Bid Monitoring'!R4=F4)),'Bid Monitoring'!C4,"") | D14: =IF(AND('Bid Monitoring'!B4<>"",IF(B4="All",TRUE(),'Bid Monitoring'!N4=B4),IF(C4="All",TRUE(),'Bid Monitoring'!L4=C4),IF(D4="All",TRUE(),'Bid Monitoring'!F4=D4),IF(E4="All",TRUE(),'Bid Monitoring'!E4=E4),IF(F4="All",TRUE(),'Bid Monitoring'!R4=F4)),'Bid Monitoring'!E4,"") | E14: =IF(AND('Bid Monitoring'!B4<>"",IF(B4="All",TRUE(),'Bid Monitoring'!N4=B4),IF(C4="All",TRUE(),'Bid Monitoring'!L4=C4),IF(D4="All",TRUE(),'Bid Monitoring'!F4=D4),IF(E4="All",TRUE(),'Bid Monitoring'!E4=E4),IF(F4="All",TRUE(),'Bid Monitoring'!R4=F4)),'Bid Monitoring'!F4,"") | F14: =IF(AND('Bid Monitoring'!B4<>"",IF(B4="All",TRUE(),'Bid Monitoring'!N4=B4),IF(C4="All",TRUE(),'Bid Monitoring'!L4=C4),IF(D4="All",TRUE(),'Bid Monitoring'!F4=D4),IF(E4="All",TRUE(),'Bid Monitoring'!E4=E4),IF(F4="All",TRUE(),'Bid Monitoring'!R4=F4)),'Bid Monitoring'!H4,"") | G14: =IF(AND('Bid Monitoring'!B4<>"",IF(B4="All",TRUE(),'Bid Monitoring'!N4=B4),IF(C4="All",TRUE(),'Bid Monitoring'!L4=C4),IF(D4="All",TRUE(),'Bid Monitoring'!F4=D4),IF(E4="All",TRUE(),'Bid Monitoring'!E4=E4),IF(F4="All",TRUE(),'Bid Monitoring'!R4=F4)),'Bid Monitoring'!I4,"") | H14: =IF(AND('Bid Monitoring'!B4<>"",IF(B4="All",TRUE(),'Bid Monitoring'!N4=B4),IF(C4="All",TRUE(),'Bid Monitoring'!L4=C4),IF(D4="All",TRUE(),'Bid Monitoring'!F4=D4),IF(E4="All",TRUE(),'Bid Monitoring'!E4=E4),IF(F4="All",TRUE(),'Bid Monitoring'!R4=F4)),'Bid Monitoring'!K4,"") | I14: =IF(AND('Bid Monitoring'!B4<>"",IF(B4="All",TRUE(),'Bid Monitoring'!N4=B4),IF(C4="All",TRUE(),'Bid Monitoring'!L4=C4),IF(D4="All",TRUE(),'Bid Monitoring'!F4=D4),IF(E4="All",TRUE(),'Bid Monitoring'!E4=E4),IF(F4="All",TRUE(),'Bid Monitoring'!R4=F4)),'Bid Monitoring'!N4,"") | J14: =IF(AND('Bid Monitoring'!B4<>"",IF(B4="All",TRUE(),'Bid Monitoring'!N4=B4),IF(C4="All",TRUE(),'Bid Monitoring'!L4=C4),IF(D4="All",TRUE(),'Bid Monitoring'!F4=D4),IF(E4="All",TRUE(),'Bid Monitoring'!E4=E4),IF(F4="All",TRUE(),'Bid Monitoring'!R4=F4)),'Bid Monitoring'!L4,"")
A15: =IF(AND('Bid Monitoring'!B5<>"",IF(B4="All",TRUE(),'Bid Monitoring'!N5=B4),IF(C4="All",TRUE(),'Bid Monitoring'!L5=C4),IF(D4="All",TRUE(),'Bid Monitoring'!F5=D4),IF(E4="All",TRUE(),'Bid Monitoring'!E5=E4),IF(F4="All",TRUE(),'Bid Monitoring'!R5=F4)),'Bid Monitoring'!B5,"") | B15: =IF(AND('Bid Monitoring'!B5<>"",IF(B4="All",TRUE(),'Bid Monitoring'!N5=B4),IF(C4="All",TRUE(),'Bid Monitoring'!L5=C4),IF(D4="All",TRUE(),'Bid Monitoring'!F5=D4),IF(E4="All",TRUE(),'Bid Monitoring'!E5=E4),IF(F4="All",TRUE(),'Bid Monitoring'!R5=F4)),'Bid Monitoring'!D5,"") | C15: =IF(AND('Bid Monitoring'!B5<>"",IF(B4="All",TRUE(),'Bid Monitoring'!N5=B4),IF(C4="All",TRUE(),'Bid Monitoring'!L5=C4),IF(D4="All",TRUE(),'Bid Monitoring'!F5=D4),IF(E4="All",TRUE(),'Bid Monitoring'!E5=E4),IF(F4="All",TRUE(),'Bid Monitoring'!R5=F4)),'Bid Monitoring'!C5,"") | D15: =IF(AND('Bid Monitoring'!B5<>"",IF(B4="All",TRUE(),'Bid Monitoring'!N5=B4),IF(C4="All",TRUE(),'Bid Monitoring'!L5=C4),IF(D4="All",TRUE(),'Bid Monitoring'!F5=D4),IF(E4="All",TRUE(),'Bid Monitoring'!E5=E4),IF(F4="All",TRUE(),'Bid Monitoring'!R5=F4)),'Bid Monitoring'!E5,"") | E15: =IF(AND('Bid Monitoring'!B5<>"",IF(B4="All",TRUE(),'Bid Monitoring'!N5=B4),IF(C4="All",TRUE(),'Bid Monitoring'!L5=C4),IF(D4="All",TRUE(),'Bid Monitoring'!F5=D4),IF(E4="All",TRUE(),'Bid Monitoring'!E5=E4),IF(F4="All",TRUE(),'Bid Monitoring'!R5=F4)),'Bid Monitoring'!F5,"") | F15: =IF(AND('Bid Monitoring'!B5<>"",IF(B4="All",TRUE(),'Bid Monitoring'!N5=B4),IF(C4="All",TRUE(),'Bid Monitoring'!L5=C4),IF(D4="All",TRUE(),'Bid Monitoring'!F5=D4),IF(E4="All",TRUE(),'Bid Monitoring'!E5=E4),IF(F4="All",TRUE(),'Bid Monitoring'!R5=F4)),'Bid Monitoring'!H5,"") | G15: =IF(AND('Bid Monitoring'!B5<>"",IF(B4="All",TRUE(),'Bid Monitoring'!N5=B4),IF(C4="All",TRUE(),'Bid Monitoring'!L5=C4),IF(D4="All",TRUE(),'Bid Monitoring'!F5=D4),IF(E4="All",TRUE(),'Bid Monitoring'!E5=E4),IF(F4="All",TRUE(),'Bid Monitoring'!R5=F4)),'Bid Monitoring'!I5,"") | H15: =IF(AND('Bid Monitoring'!B5<>"",IF(B4="All",TRUE(),'Bid Monitoring'!N5=B4),IF(C4="All",TRUE(),'Bid Monitoring'!L5=C4),IF(D4="All",TRUE(),'Bid Monitoring'!F5=D4),IF(E4="All",TRUE(),'Bid Monitoring'!E5=E4),IF(F4="All",TRUE(),'Bid Monitoring'!R5=F4)),'Bid Monitoring'!K5,"") | I15: =IF(AND('Bid Monitoring'!B5<>"",IF(B4="All",TRUE(),'Bid Monitoring'!N5=B4),IF(C4="All",TRUE(),'Bid Monitoring'!L5=C4),IF(D4="All",TRUE(),'Bid Monitoring'!F5=D4),IF(E4="All",TRUE(),'Bid Monitoring'!E5=E4),IF(F4="All",TRUE(),'Bid Monitoring'!R5=F4)),'Bid Monitoring'!N5,"") | J15: =IF(AND('Bid Monitoring'!B5<>"",IF(B4="All",TRUE(),'Bid Monitoring'!N5=B4),IF(C4="All",TRUE(),'Bid Monitoring'!L5=C4),IF(D4="All",TRUE(),'Bid Monitoring'!F5=D4),IF(E4="All",TRUE(),'Bid Monitoring'!E5=E4),IF(F4="All",TRUE(),'Bid Monitoring'!R5=F4)),'Bid Monitoring'!L5,"")
A16: =IF(AND('Bid Monitoring'!B6<>"",IF(B4="All",TRUE(),'Bid Monitoring'!N6=B4),IF(C4="All",TRUE(),'Bid Monitoring'!L6=C4),IF(D4="All",TRUE(),'Bid Monitoring'!F6=D4),IF(E4="All",TRUE(),'Bid Monitoring'!E6=E4),IF(F4="All",TRUE(),'Bid Monitoring'!R6=F4)),'Bid Monitoring'!B6,"") | B16: =IF(AND('Bid Monitoring'!B6<>"",IF(B4="All",TRUE(),'Bid Monitoring'!N6=B4),IF(C4="All",TRUE(),'Bid Monitoring'!L6=C4),IF(D4="All",TRUE(),'Bid Monitoring'!F6=D4),IF(E4="All",TRUE(),'Bid Monitoring'!E6=E4),IF(F4="All",TRUE(),'Bid Monitoring'!R6=F4)),'Bid Monitoring'!D6,"") | C16: =IF(AND('Bid Monitoring'!B6<>"",IF(B4="All",TRUE(),'Bid Monitoring'!N6=B4),IF(C4="All",TRUE(),'Bid Monitoring'!L6=C4),IF(D4="All",TRUE(),'Bid Monitoring'!F6=D4),IF(E4="All",TRUE(),'Bid Monitoring'!E6=E4),IF(F4="All",TRUE(),'Bid Monitoring'!R6=F4)),'Bid Monitoring'!C6,"") | D16: =IF(AND('Bid Monitoring'!B6<>"",IF(B4="All",TRUE(),'Bid Monitoring'!N6=B4),IF(C4="All",TRUE(),'Bid Monitoring'!L6=C4),IF(D4="All",TRUE(),'Bid Monitoring'!F6=D4),IF(E4="All",TRUE(),'Bid Monitoring'!E6=E4),IF(F4="All",TRUE(),'Bid Monitoring'!R6=F4)),'Bid Monitoring'!E6,"") | E16: =IF(AND('Bid Monitoring'!B6<>"",IF(B4="All",TRUE(),'Bid Monitoring'!N6=B4),IF(C4="All",TRUE(),'Bid Monitoring'!L6=C4),IF(D4="All",TRUE(),'Bid Monitoring'!F6=D4),IF(E4="All",TRUE(),'Bid Monitoring'!E6=E4),IF(F4="All",TRUE(),'Bid Monitoring'!R6=F4)),'Bid Monitoring'!F6,"") | F16: =IF(AND('Bid Monitoring'!B6<>"",IF(B4="All",TRUE(),'Bid Monitoring'!N6=B4),IF(C4="All",TRUE(),'Bid Monitoring'!L6=C4),IF(D4="All",TRUE(),'Bid Monitoring'!F6=D4),IF(E4="All",TRUE(),'Bid Monitoring'!E6=E4),IF(F4="All",TRUE(),'Bid Monitoring'!R6=F4)),'Bid Monitoring'!H6,"") | G16: =IF(AND('Bid Monitoring'!B6<>"",IF(B4="All",TRUE(),'Bid Monitoring'!N6=B4),IF(C4="All",TRUE(),'Bid Monitoring'!L6=C4),IF(D4="All",TRUE(),'Bid Monitoring'!F6=D4),IF(E4="All",TRUE(),'Bid Monitoring'!E6=E4),IF(F4="All",TRUE(),'Bid Monitoring'!R6=F4)),'Bid Monitoring'!I6,"") | H16: =IF(AND('Bid Monitoring'!B6<>"",IF(B4="All",TRUE(),'Bid Monitoring'!N6=B4),IF(C4="All",TRUE(),'Bid Monitoring'!L6=C4),IF(D4="All",TRUE(),'Bid Monitoring'!F6=D4),IF(E4="All",TRUE(),'Bid Monitoring'!E6=E4),IF(F4="All",TRUE(),'Bid Monitoring'!R6=F4)),'Bid Monitoring'!K6,"") | I16: =IF(AND('Bid Monitoring'!B6<>"",IF(B4="All",TRUE(),'Bid Monitoring'!N6=B4),IF(C4="All",TRUE(),'Bid Monitoring'!L6=C4),IF(D4="All",TRUE(),'Bid Monitoring'!F6=D4),IF(E4="All",TRUE(),'Bid Monitoring'!E6=E4),IF(F4="All",TRUE(),'Bid Monitoring'!R6=F4)),'Bid Monitoring'!N6,"") | J16: =IF(AND('Bid Monitoring'!B6<>"",IF(B4="All",TRUE(),'Bid Monitoring'!N6=B4),IF(C4="All",TRUE(),'Bid Monitoring'!L6=C4),IF(D4="All",TRUE(),'Bid Monitoring'!F6=D4),IF(E4="All",TRUE(),'Bid Monitoring'!E6=E4),IF(F4="All",TRUE(),'Bid Monitoring'!R6=F4)),'Bid Monitoring'!L6,"")
A17: =IF(AND('Bid Monitoring'!B7<>"",IF(B4="All",TRUE(),'Bid Monitoring'!N7=B4),IF(C4="All",TRUE(),'Bid Monitoring'!L7=C4),IF(D4="All",TRUE(),'Bid Monitoring'!F7=D4),IF(E4="All",TRUE(),'Bid Monitoring'!E7=E4),IF(F4="All",TRUE(),'Bid Monitoring'!R7=F4)),'Bid Monitoring'!B7,"") | B17: =IF(AND('Bid Monitoring'!B7<>"",IF(B4="All",TRUE(),'Bid Monitoring'!N7=B4),IF(C4="All",TRUE(),'Bid Monitoring'!L7=C4),IF(D4="All",TRUE(),'Bid Monitoring'!F7=D4),IF(E4="All",TRUE(),'Bid Monitoring'!E7=E4),IF(F4="All",TRUE(),'Bid Monitoring'!R7=F4)),'Bid Monitoring'!D7,"") | C17: =IF(AND('Bid Monitoring'!B7<>"",IF(B4="All",TRUE(),'Bid Monitoring'!N7=B4),IF(C4="All",TRUE(),'Bid Monitoring'!L7=C4),IF(D4="All",TRUE(),'Bid Monitoring'!F7=D4),IF(E4="All",TRUE(),'Bid Monitoring'!E7=E4),IF(F4="All",TRUE(),'Bid Monitoring'!R7=F4)),'Bid Monitoring'!C7,"") | D17: =IF(AND('Bid Monitoring'!B7<>"",IF(B4="All",TRUE(),'Bid Monitoring'!N7=B4),IF(C4="All",TRUE(),'Bid Monitoring'!L7=C4),IF(D4="All",TRUE(),'Bid Monitoring'!F7=D4),IF(E4="All",TRUE(),'Bid Monitoring'!E7=E4),IF(F4="All",TRUE(),'Bid Monitoring'!R7=F4)),'Bid Monitoring'!E7,"") | E17: =IF(AND('Bid Monitoring'!B7<>"",IF(B4="All",TRUE(),'Bid Monitoring'!N7=B4),IF(C4="All",TRUE(),'Bid Monitoring'!L7=C4),IF(D4="All",TRUE(),'Bid Monitoring'!F7=D4),IF(E4="All",TRUE(),'Bid Monitoring'!E7=E4),IF(F4="All",TRUE(),'Bid Monitoring'!R7=F4)),'Bid Monitoring'!F7,"") | F17: =IF(AND('Bid Monitoring'!B7<>"",IF(B4="All",TRUE(),'Bid Monitoring'!N7=B4),IF(C4="All",TRUE(),'Bid Monitoring'!L7=C4),IF(D4="All",TRUE(),'Bid Monitoring'!F7=D4),IF(E4="All",TRUE(),'Bid Monitoring'!E7=E4),IF(F4="All",TRUE(),'Bid Monitoring'!R7=F4)),'Bid Monitoring'!H7,"") | G17: =IF(AND('Bid Monitoring'!B7<>"",IF(B4="All",TRUE(),'Bid Monitoring'!N7=B4),IF(C4="All",TRUE(),'Bid Monitoring'!L7=C4),IF(D4="All",TRUE(),'Bid Monitoring'!F7=D4),IF(E4="All",TRUE(),'Bid Monitoring'!E7=E4),IF(F4="All",TRUE(),'Bid Monitoring'!R7=F4)),'Bid Monitoring'!I7,"") | H17: =IF(AND('Bid Monitoring'!B7<>"",IF(B4="All",TRUE(),'Bid Monitoring'!N7=B4),IF(C4="All",TRUE(),'Bid Monitoring'!L7=C4),IF(D4="All",TRUE(),'Bid Monitoring'!F7=D4),IF(E4="All",TRUE(),'Bid Monitoring'!E7=E4),IF(F4="All",TRUE(),'Bid Monitoring'!R7=F4)),'Bid Monitoring'!K7,"") | I17: =IF(AND('Bid Monitoring'!B7<>"",IF(B4="All",TRUE(),'Bid Monitoring'!N7=B4),IF(C4="All",TRUE(),'Bid Monitoring'!L7=C4),IF(D4="All",TRUE(),'Bid Monitoring'!F7=D4),IF(E4="All",TRUE(),'Bid Monitoring'!E7=E4),IF(F4="All",TRUE(),'Bid Monitoring'!R7=F4)),'Bid Monitoring'!N7,"") | J17: =IF(AND('Bid Monitoring'!B7<>"",IF(B4="All",TRUE(),'Bid Monitoring'!N7=B4),IF(C4="All",TRUE(),'Bid Monitoring'!L7=C4),IF(D4="All",TRUE(),'Bid Monitoring'!F7=D4),IF(E4="All",TRUE(),'Bid Monitoring'!E7=E4),IF(F4="All",TRUE(),'Bid Monitoring'!R7=F4)),'Bid Monitoring'!L7,"")
A18: =IF(AND('Bid Monitoring'!B8<>"",IF(B4="All",TRUE(),'Bid Monitoring'!N8=B4),IF(C4="All",TRUE(),'Bid Monitoring'!L8=C4),IF(D4="All",TRUE(),'Bid Monitoring'!F8=D4),IF(E4="All",TRUE(),'Bid Monitoring'!E8=E4),IF(F4="All",TRUE(),'Bid Monitoring'!R8=F4)),'Bid Monitoring'!B8,"") | B18: =IF(AND('Bid Monitoring'!B8<>"",IF(B4="All",TRUE(),'Bid Monitoring'!N8=B4),IF(C4="All",TRUE(),'Bid Monitoring'!L8=C4),IF(D4="All",TRUE(),'Bid Monitoring'!F8=D4),IF(E4="All",TRUE(),'Bid Monitoring'!E8=E4),IF(F4="All",TRUE(),'Bid Monitoring'!R8=F4)),'Bid Monitoring'!D8,"") | C18: =IF(AND('Bid Monitoring'!B8<>"",IF(B4="All",TRUE(),'Bid Monitoring'!N8=B4),IF(C4="All",TRUE(),'Bid Monitoring'!L8=C4),IF(D4="All",TRUE(),'Bid Monitoring'!F8=D4),IF(E4="All",TRUE(),'Bid Monitoring'!E8=E4),IF(F4="All",TRUE(),'Bid Monitoring'!R8=F4)),'Bid Monitoring'!C8,"") | D18: =IF(AND('Bid Monitoring'!B8<>"",IF(B4="All",TRUE(),'Bid Monitoring'!N8=B4),IF(C4="All",TRUE(),'Bid Monitoring'!L8=C4),IF(D4="All",TRUE(),'Bid Monitoring'!F8=D4),IF(E4="All",TRUE(),'Bid Monitoring'!E8=E4),IF(F4="All",TRUE(),'Bid Monitoring'!R8=F4)),'Bid Monitoring'!E8,"") | E18: =IF(AND('Bid Monitoring'!B8<>"",IF(B4="All",TRUE(),'Bid Monitoring'!N8=B4),IF(C4="All",TRUE(),'Bid Monitoring'!L8=C4),IF(D4="All",TRUE(),'Bid Monitoring'!F8=D4),IF(E4="All",TRUE(),'Bid Monitoring'!E8=E4),IF(F4="All",TRUE(),'Bid Monitoring'!R8=F4)),'Bid Monitoring'!F8,"") | F18: =IF(AND('Bid Monitoring'!B8<>"",IF(B4="All",TRUE(),'Bid Monitoring'!N8=B4),IF(C4="All",TRUE(),'Bid Monitoring'!L8=C4),IF(D4="All",TRUE(),'Bid Monitoring'!F8=D4),IF(E4="All",TRUE(),'Bid Monitoring'!E8=E4),IF(F4="All",TRUE(),'Bid Monitoring'!R8=F4)),'Bid Monitoring'!H8,"") | G18: =IF(AND('Bid Monitoring'!B8<>"",IF(B4="All",TRUE(),'Bid Monitoring'!N8=B4),IF(C4="All",TRUE(),'Bid Monitoring'!L8=C4),IF(D4="All",TRUE(),'Bid Monitoring'!F8=D4),IF(E4="All",TRUE(),'Bid Monitoring'!E8=E4),IF(F4="All",TRUE(),'Bid Monitoring'!R8=F4)),'Bid Monitoring'!I8,"") | H18: =IF(AND('Bid Monitoring'!B8<>"",IF(B4="All",TRUE(),'Bid Monitoring'!N8=B4),IF(C4="All",TRUE(),'Bid Monitoring'!L8=C4),IF(D4="All",TRUE(),'Bid Monitoring'!F8=D4),IF(E4="All",TRUE(),'Bid Monitoring'!E8=E4),IF(F4="All",TRUE(),'Bid Monitoring'!R8=F4)),'Bid Monitoring'!K8,"") | I18: =IF(AND('Bid Monitoring'!B8<>"",IF(B4="All",TRUE(),'Bid Monitoring'!N8=B4),IF(C4="All",TRUE(),'Bid Monitoring'!L8=C4),IF(D4="All",TRUE(),'Bid Monitoring'!F8=D4),IF(E4="All",TRUE(),'Bid Monitoring'!E8=E4),IF(F4="All",TRUE(),'Bid Monitoring'!R8=F4)),'Bid Monitoring'!N8,"") | J18: =IF(AND('Bid Monitoring'!B8<>"",IF(B4="All",TRUE(),'Bid Monitoring'!N8=B4),IF(C4="All",TRUE(),'Bid Monitoring'!L8=C4),IF(D4="All",TRUE(),'Bid Monitoring'!F8=D4),IF(E4="All",TRUE(),'Bid Monitoring'!E8=E4),IF(F4="All",TRUE(),'Bid Monitoring'!R8=F4)),'Bid Monitoring'!L8,"")
A19: =IF(AND('Bid Monitoring'!B9<>"",IF(B4="All",TRUE(),'Bid Monitoring'!N9=B4),IF(C4="All",TRUE(),'Bid Monitoring'!L9=C4),IF(D4="All",TRUE(),'Bid Monitoring'!F9=D4),IF(E4="All",TRUE(),'Bid Monitoring'!E9=E4),IF(F4="All",TRUE(),'Bid Monitoring'!R9=F4)),'Bid Monitoring'!B9,"") | B19: =IF(AND('Bid Monitoring'!B9<>"",IF(B4="All",TRUE(),'Bid Monitoring'!N9=B4),IF(C4="All",TRUE(),'Bid Monitoring'!L9=C4),IF(D4="All",TRUE(),'Bid Monitoring'!F9=D4),IF(E4="All",TRUE(),'Bid Monitoring'!E9=E4),IF(F4="All",TRUE(),'Bid Monitoring'!R9=F4)),'Bid Monitoring'!D9,"") | C19: =IF(AND('Bid Monitoring'!B9<>"",IF(B4="All",TRUE(),'Bid Monitoring'!N9=B4),IF(C4="All",TRUE(),'Bid Monitoring'!L9=C4),IF(D4="All",TRUE(),'Bid Monitoring'!F9=D4),IF(E4="All",TRUE(),'Bid Monitoring'!E9=E4),IF(F4="All",TRUE(),'Bid Monitoring'!R9=F4)),'Bid Monitoring'!C9,"") | D19: =IF(AND('Bid Monitoring'!B9<>"",IF(B4="All",TRUE(),'Bid Monitoring'!N9=B4),IF(C4="All",TRUE(),'Bid Monitoring'!L9=C4),IF(D4="All",TRUE(),'Bid Monitoring'!F9=D4),IF(E4="All",TRUE(),'Bid Monitoring'!E9=E4),IF(F4="All",TRUE(),'Bid Monitoring'!R9=F4)),'Bid Monitoring'!E9,"") | E19: =IF(AND('Bid Monitoring'!B9<>"",IF(B4="All",TRUE(),'Bid Monitoring'!N9=B4),IF(C4="All",TRUE(),'Bid Monitoring'!L9=C4),IF(D4="All",TRUE(),'Bid Monitoring'!F9=D4),IF(E4="All",TRUE(),'Bid Monitoring'!E9=E4),IF(F4="All",TRUE(),'Bid Monitoring'!R9=F4)),'Bid Monitoring'!F9,"") | F19: =IF(AND('Bid Monitoring'!B9<>"",IF(B4="All",TRUE(),'Bid Monitoring'!N9=B4),IF(C4="All",TRUE(),'Bid Monitoring'!L9=C4),IF(D4="All",TRUE(),'Bid Monitoring'!F9=D4),IF(E4="All",TRUE(),'Bid Monitoring'!E9=E4),IF(F4="All",TRUE(),'Bid Monitoring'!R9=F4)),'Bid Monitoring'!H9,"") | G19: =IF(AND('Bid Monitoring'!B9<>"",IF(B4="All",TRUE(),'Bid Monitoring'!N9=B4),IF(C4="All",TRUE(),'Bid Monitoring'!L9=C4),IF(D4="All",TRUE(),'Bid Monitoring'!F9=D4),IF(E4="All",TRUE(),'Bid Monitoring'!E9=E4),IF(F4="All",TRUE(),'Bid Monitoring'!R9=F4)),'Bid Monitoring'!I9,"") | H19: =IF(AND('Bid Monitoring'!B9<>"",IF(B4="All",TRUE(),'Bid Monitoring'!N9=B4),IF(C4="All",TRUE(),'Bid Monitoring'!L9=C4),IF(D4="All",TRUE(),'Bid Monitoring'!F9=D4),IF(E4="All",TRUE(),'Bid Monitoring'!E9=E4),IF(F4="All",TRUE(),'Bid Monitoring'!R9=F4)),'Bid Monitoring'!K9,"") | I19: =IF(AND('Bid Monitoring'!B9<>"",IF(B4="All",TRUE(),'Bid Monitoring'!N9=B4),IF(C4="All",TRUE(),'Bid Monitoring'!L9=C4),IF(D4="All",TRUE(),'Bid Monitoring'!F9=D4),IF(E4="All",TRUE(),'Bid Monitoring'!E9=E4),IF(F4="All",TRUE(),'Bid Monitoring'!R9=F4)),'Bid Monitoring'!N9,"") | J19: =IF(AND('Bid Monitoring'!B9<>"",IF(B4="All",TRUE(),'Bid Monitoring'!N9=B4),IF(C4="All",TRUE(),'Bid Monitoring'!L9=C4),IF(D4="All",TRUE(),'Bid Monitoring'!F9=D4),IF(E4="All",TRUE(),'Bid Monitoring'!E9=E4),IF(F4="All",TRUE(),'Bid Monitoring'!R9=F4)),'Bid Monitoring'!L9,"")
A20: =IF(AND('Bid Monitoring'!B10<>"",IF(B4="All",TRUE(),'Bid Monitoring'!N10=B4),IF(C4="All",TRUE(),'Bid Monitoring'!L10=C4),IF(D4="All",TRUE(),'Bid Monitoring'!F10=D4),IF(E4="All",TRUE(),'Bid Monitoring'!E10=E4),IF(F4="All",TRUE(),'Bid Monitoring'!R10=F4)),'Bid Monitoring'!B10,"") | B20: =IF(AND('Bid Monitoring'!B10<>"",IF(B4="All",TRUE(),'Bid Monitoring'!N10=B4),IF(C4="All",TRUE(),'Bid Monitoring'!L10=C4),IF(D4="All",TRUE(),'Bid Monitoring'!F10=D4),IF(E4="All",TRUE(),'Bid Monitoring'!E10=E4),IF(F4="All",TRUE(),'Bid Monitoring'!R10=F4)),'Bid Monitoring'!D10,"") | C20: =IF(AND('Bid Monitoring'!B10<>"",IF(B4="All",TRUE(),'Bid Monitoring'!N10=B4),IF(C4="All",TRUE(),'Bid Monitoring'!L10=C4),IF(D4="All",TRUE(),'Bid Monitoring'!F10=D4),IF(E4="All",TRUE(),'Bid Monitoring'!E10=E4),IF(F4="All",TRUE(),'Bid Monitoring'!R10=F4)),'Bid Monitoring'!C10,"") | D20: =IF(AND('Bid Monitoring'!B10<>"",IF(B4="All",TRUE(),'Bid Monitoring'!N10=B4),IF(C4="All",TRUE(),'Bid Monitoring'!L10=C4),IF(D4="All",TRUE(),'Bid Monitoring'!F10=D4),IF(E4="All",TRUE(),'Bid Monitoring'!E10=E4),IF(F4="All",TRUE(),'Bid Monitoring'!R10=F4)),'Bid Monitoring'!E10,"") | E20: =IF(AND('Bid Monitoring'!B10<>"",IF(B4="All",TRUE(),'Bid Monitoring'!N10=B4),IF(C4="All",TRUE(),'Bid Monitoring'!L10=C4),IF(D4="All",TRUE(),'Bid Monitoring'!F10=D4),IF(E4="All",TRUE(),'Bid Monitoring'!E10=E4),IF(F4="All",TRUE(),'Bid Monitoring'!R10=F4)),'Bid Monitoring'!F10,"") | F20: =IF(AND('Bid Monitoring'!B10<>"",IF(B4="All",TRUE(),'Bid Monitoring'!N10=B4),IF(C4="All",TRUE(),'Bid Monitoring'!L10=C4),IF(D4="All",TRUE(),'Bid Monitoring'!F10=D4),IF(E4="All",TRUE(),'Bid Monitoring'!E10=E4),IF(F4="All",TRUE(),'Bid Monitoring'!R10=F4)),'Bid Monitoring'!H10,"") | G20: =IF(AND('Bid Monitoring'!B10<>"",IF(B4="All",TRUE(),'Bid Monitoring'!N10=B4),IF(C4="All",TRUE(),'Bid Monitoring'!L10=C4),IF(D4="All",TRUE(),'Bid Monitoring'!F10=D4),IF(E4="All",TRUE(),'Bid Monitoring'!E10=E4),IF(F4="All",TRUE(),'Bid Monitoring'!R10=F4)),'Bid Monitoring'!I10,"") | H20: =IF(AND('Bid Monitoring'!B10<>"",IF(B4="All",TRUE(),'Bid Monitoring'!N10=B4),IF(C4="All",TRUE(),'Bid Monitoring'!L10=C4),IF(D4="All",TRUE(),'Bid Monitoring'!F10=D4),IF(E4="All",TRUE(),'Bid Monitoring'!E10=E4),IF(F4="All",TRUE(),'Bid Monitoring'!R10=F4)),'Bid Monitoring'!K10,"") | I20: =IF(AND('Bid Monitoring'!B10<>"",IF(B4="All",TRUE(),'Bid Monitoring'!N10=B4),IF(C4="All",TRUE(),'Bid Monitoring'!L10=C4),IF(D4="All",TRUE(),'Bid Monitoring'!F10=D4),IF(E4="All",TRUE(),'Bid Monitoring'!E10=E4),IF(F4="All",TRUE(),'Bid Monitoring'!R10=F4)),'Bid Monitoring'!N10,"") | J20: =IF(AND('Bid Monitoring'!B10<>"",IF(B4="All",TRUE(),'Bid Monitoring'!N10=B4),IF(C4="All",TRUE(),'Bid Monitoring'!L10=C4),IF(D4="All",TRUE(),'Bid Monitoring'!F10=D4),IF(E4="All",TRUE(),'Bid Monitoring'!E10=E4),IF(F4="All",TRUE(),'Bid Monitoring'!R10=F4)),'Bid Monitoring'!L10,"")
